Workbook

Sheet Registre de reserves
A1: ANY | B1: MES | C1: DATA | D1: DIA | E1: FESTIU | F1: ESPECIAL | G1: HORA ENTRADA | H1: HORA SORTIDA | I1: HORARI | J1: TORNS | K1: NOM CLIENT | L1: CODI POSTAL | M1: MUNICIPI | N1: DIRECCIÓ | O1: DNI | P1: TARIFA | Q1: HORAS EXTRAS | R1: IMPORTE EXTRAS | S1: IMPORTE TOTAL | T1: COBRAT | U1: RES-A | V1: RES-B | W1: EXTR-A | X1: EXTR-B | Y1: OBSERVACIONS | Z1: Columna1 | AA1: Columna2
A2: 2020 | B2: GENER | C2: 43831 | D2: DIMECRES | E2: SI | F2: NO | G2: 0.52083333 | H2: 0.85416667 | I2: DINAR | J2: 2 | P2: 200 | Q2: 0 | R2: 0 | S2: =Tabla1[[#This Row],[TARIFA]]+Tabla1[[#This Row],[IMPORTE EXTRAS]] -> 200 | T2: SI | U2: 0 | V2: 200 | W2: 0 | X2: 0 | Y2: ANUAL | Z2: =SUM(Tabla1[[#This Row],[RES-A]:[EXTR-B]]) -> 200 | AA2: =Tabla1[[#This Row],[Columna1]]-Tabla1[[#This Row],[IMPORTE TOTAL]] -> 0
A3: 2020 | B3: GENER | C3: 43832 | D3: DIJOUS | E3: NO | F3: NO | G3: 0.64583333 | H3: 0.85416667 | I3: TARDA | J3: 2 | P3: 95 | Q3: 0 | R3: 0 | S3: =Tabla1[[#This Row],[TARIFA]]+Tabla1[[#This Row],[IMPORTE EXTRAS]] -> 95 | T3: SI | U3: 5 | V3: 90 | W3: 0 | X3: 0 | Z3: =SUM(Tabla1[[#This Row],[RES-A]:[EXTR-B]]) -> 95 | AA3: =Tabla1[[#This Row],[Columna1]]-Tabla1[[#This Row],[IMPORTE TOTAL]] -> 0
A4: 2020 | B4: GENER | C4: 43833 | D4: DIVENDRES | E4: NO | F4: NO | G4: 0.64583333 | H4: 0.85416667 | I4: TARDA | J4: 1 | P4: 135 | Q4: 0 | R4: 0 | S4: =Tabla1[[#This Row],[TARIFA]]+Tabla1[[#This Row],[IMPORTE EXTRAS]] -> 135 | T4: SI | U4: 135 | V4: 0 | W4: 0 | X4: 0 | Z4: =SUM(Tabla1[[#This Row],[RES-A]:[EXTR-B]]) -> 135 | AA4: =Tabla1[[#This Row],[Columna1]]-Tabla1[[#This Row],[IMPORTE TOTAL]] -> 0
A5: 2020 | B5: GENER | C5: 43833 | D5: DIVENDRES | E5: NO | F5: NO | G5: 0.89583333 | H5: 0.10416667 | I5: NIT | J5: 1 | P5: 195 | Q5: 0 | R5: 0 | S5: =Tabla1[[#This Row],[TARIFA]]+Tabla1[[#This Row],[IMPORTE EXTRAS]] -> 195 | T5: SI | U5: 0 | V5: 195 | W5: 0 | X5: 0 | Z5: =SUM(Tabla1[[#This Row],[RES-A]:[EXTR-B]]) -> 195 | AA5: =Tabla1[[#This Row],[Columna1]]-Tabla1[[#This Row],[IMPORTE TOTAL]] -> 0
A6: 2020 | B6: GENER | C6: 43834 | D6: DISSABTE | E6: NO | F6: NO | G6: 0.39583333 | H6: 0.60416667 | I6: MATI | J6: 1 | P6: 145 | Q6: 0 | R6: 0 | S6: =Tabla1[[#This Row],[TARIFA]]+Tabla1[[#This Row],[IMPORTE EXTRAS]] -> 145 | T6: SI | U6: 0 | V6: 145 | W6: 0 | X6: 0 | Z6: =SUM(Tabla1[[#This Row],[RES-A]:[EXTR-B]]) -> 145 | AA6: =Tabla1[[#This Row],[Columna1]]-Tabla1[[#This Row],[IMPORTE TOTAL]] -> 0
A7: 2020 | B7: GENER | C7: 43834 | D7: DISSABTE | E7: NO | F7: NO | G7: 0.64583333 | H7: 0.85416667 | I7: TARDA | J7: 1 | P7: 145 | Q7: 0 | R7: 0 | S7: =Tabla1[[#This Row],[TARIFA]]+Tabla1[[#This Row],[IMPORTE EXTRAS]] -> 145 | T7: SI | U7: 145 | V7: 0 | W7: 0 | X7: 0 | Z7: =SUM(Tabla1[[#This Row],[RES-A]:[EXTR-B]]) -> 145 | AA7: =Tabla1[[#This Row],[Columna1]]-Tabla1[[#This Row],[IMPORTE TOTAL]] -> 0
A8: 2020 | B8: GENER | C8: 43834 | D8: DISSABTE | E8: NO | F8: NO | G8: 0.89583333 | H8: 0.10416667 | I8: NIT | J8: 1 | P8: 195 | Q8: 0 | R8: 0 | S8: =Tabla1[[#This Row],[TARIFA]]+Tabla1[[#This Row],[IMPORTE EXTRAS]] -> 195 | T8: SI | U8: 195 | V8: 0 | W8: 0 | X8: 0 | Z8: =SUM(Tabla1[[#This Row],[RES-A]:[EXTR-B]]) -> 195 | AA8: =Tabla1[[#This Row],[Columna1]]-Tabla1[[#This Row],[IMPORTE TOTAL]] -> 0
A9: 2020 | B9: GENER | C9: 43835 | D9: DIUMENGE | E9: NO | F9: SI | G9: 0.39583333 | H9: 0.60416667 | I9: MATI | J9: 1 | P9: 145 | Q9: 0 | R9: 0 | S9: =Tabla1[[#This Row],[TARIFA]]+Tabla1[[#This Row],[IMPORTE EXTRAS]] -> 145 | T9: SI | U9: 145 | V9: 0 | W9: 0 | X9: 0 | Z9: =SUM(Tabla1[[#This Row],[RES-A]:[EXTR-B]]) -> 145 | AA9: =Tabla1[[#This Row],[Columna1]]-Tabla1[[#This Row],[IMPORTE TOTAL]] -> 0
A10: 2020 | B10: GENER | C10: 43836 | D10: DILLUNS | E10: SI | F10: NO | G10: 0.625 | H10: 0.83333333 | I10: DINAR | J10: 1 | P10: 145 | Q10: 0 | R10: 0 | S10: =Tabla1[[#This Row],[TARIFA]]+Tabla1[[#This Row],[IMPORTE EXTRAS]] -> 145 | T10: SI | U10: 145 | V10: 0 | W10: 0 | X10: 0 | Y10: ANUAL | Z10: =SUM(Tabla1[[#This Row],[RES-A]:[EXTR-B]]) -> 145 | AA10: =Tabla1[[#This Row],[Columna1]]-Tabla1[[#This Row],[IMPORTE TOTAL]] -> 0
A11: 2020 | B11: GENER | C11: 43838 | D11: DIMECRES | E11: NO | F11: NO | G11: 0.64583333 | H11: 0.85416667 | I11: TARDA | J11: 1 | P11: 95 | Q11: 0 | R11: 0 | S11: =Tabla1[[#This Row],[TARIFA]]+Tabla1[[#This Row],[IMPORTE EXTRAS]] -> 95 | T11: SI | U11: 0 | V11: 95 | W11: 0 | X11: 0 | Z11: =SUM(Tabla1[[#This Row],[RES-A]:[EXTR-B]]) -> 95 | AA11: =Tabla1[[#This Row],[Columna1]]-Tabla1[[#This Row],[IMPORTE TOTAL]] -> 0
A12: 2020 | B12: GENER | C12: 43841 | D12: DISSABTE | E12: NO | F12: NO | G12: 0.64583333 | H12: 0.10416667 | I12: TARDA+NIT | J12: 2 | P12: 300 | Q12: 0 | R12: 0 | S12: =Tabla1[[#This Row],[TARIFA]]+Tabla1[[#This Row],[IMPORTE EXTRAS]] -> 300 | T12: SI | U12: 300 | V12: 0 | W12: 0 | X12: 0 | Z12: =SUM(Tabla1[[#This Row],[RES-A]:[EXTR-B]]) -> 300 | AA12: =Tabla1[[#This Row],[Columna1]]-Tabla1[[#This Row],[IMPORTE TOTAL]] -> 0
A13: 2020 | B13: GENER | C13: 43842 | D13: DIUMENGE | E13: NO | F13: NO | G13: 0.39583333 | H13: 0.85416667 | I13: DIA SENCER | J13: 2 | P13: 200 | Q13: 0 | R13: 0 | S13: =Tabla1[[#This Row],[TARIFA]]+Tabla1[[#This Row],[IMPORTE EXTRAS]] -> 200 | T13: SI | U13: 200 | V13: 0 | W13: 0 | X13: 0 | Z13: =SUM(Tabla1[[#This Row],[RES-A]:[EXTR-B]]) -> 200 | AA13: =Tabla1[[#This Row],[Columna1]]-Tabla1[[#This Row],[IMPORTE TOTAL]] -> 0
A14: 2020 | B14: GENER | C14: 43847 | D14: DIVENDRES | E14: NO | F14: NO | G14: 0.89583333 | H14: 0.10416667 | I14: NIT | J14: 1 | P14: 195 | Q14: 1 | R14: 50 | S14: =Tabla1[[#This Row],[TARIFA]]+Tabla1[[#This Row],[IMPORTE EXTRAS]] -> 245 | T14: SI | U14: 195 | V14: 0 | W14: 0 | X14: 50 | Z14: =SUM(Tabla1[[#This Row],[RES-A]:[EXTR-B]]) -> 245 | AA14: =Tabla1[[#This Row],[Columna1]]-Tabla1[[#This Row],[IMPORTE TOTAL]] -> 0
A15: 2020 | B15: GENER | C15: 43848 | D15: DISSABTE | E15: NO | F15: NO | G15: 0.64583333 | H15: 0.85416667 | I15: TARDA | J15: 1 | P15: 145 | Q15: 0 | R15: 0 | S15: =Tabla1[[#This Row],[TARIFA]]+Tabla1[[#This Row],[IMPORTE EXTRAS]] -> 145 | T15: SI | U15: 100 | V15: 45 | W15: 0 | X15: 0 | Z15: =SUM(Tabla1[[#This Row],[RES-A]:[EXTR-B]]) -> 145 | AA15: =Tabla1[[#This Row],[Columna1]]-Tabla1[[#This Row],[IMPORTE TOTAL]] -> 0
A16: 2020 | B16: GENER | C16: 43848 | D16: DISSABTE | E16: NO | F16: NO | G16: 0.89583333 | H16: 0.10416667 | I16: NIT | J16: 1 | P16: 195 | Q16: 0 | R16: 0 | S16: =Tabla1[[#This Row],[TARIFA]]+Tabla1[[#This Row],[IMPORTE EXTRAS]] -> 195 | T16: SI | U16: 0 | V16: 195 | W16: 0 | X16: 0 | Z16: =SUM(Tabla1[[#This Row],[RES-A]:[EXTR-B]]) -> 195 | AA16: =Tabla1[[#This Row],[Columna1]]-Tabla1[[#This Row],[IMPORTE TOTAL]] -> 0
A17: 2020 | B17: GENER | C17: 43849 | D17: DIUMENGE | E17: NO | F17: NO | G17: 0.64583333 | H17: 0.85416667 | I17: TARDA | J17: 1 | P17: 145 | Q17: 0 | R17: 0 | S17: =Tabla1[[#This Row],[TARIFA]]+Tabla1[[#This Row],[IMPORTE EXTRAS]] -> 145 | T17: SI | U17: 0 | V17: 145 | W17: 0 | X17: 0 | Z17: =SUM(Tabla1[[#This Row],[RES-A]:[EXTR-B]]) -> 145 | AA17: =Tabla1[[#This Row],[Columna1]]-Tabla1[[#This Row],[IMPORTE TOTAL]] -> 0
A18: 2020 | B18: GENER | C18: 43855 | D18: DISSABTE | E18: NO | F18: NO | G18: 0.39583333 | H18: 0.60416667 | I18: MATI | J18: 1 | P18: 145 | Q18: 0 | R18: 0 | S18: =Tabla1[[#This Row],[TARIFA]]+Tabla1[[#This Row],[IMPORTE EXTRAS]] -> 145 | T18: SI | U18: 50 | V18: 95 | W18: 0 | X18: 0 | Z18: =SUM(Tabla1[[#This Row],[RES-A]:[EXTR-B]]) -> 145 | AA18: =Tabla1[[#This Row],[Columna1]]-Tabla1[[#This Row],[IMPORTE TOTAL]] -> 0
A19: 2020 | B19: GENER | C19: 43855 | D19: DISSABTE | E19: NO | F19: NO | G19: 0.89583333 | H19: 0.10416667 | I19: NIT | J19: 1 | P19: 195 | Q19: 0 | R19: 0 | S19: =Tabla1[[#This Row],[TARIFA]]+Tabla1[[#This Row],[IMPORTE EXTRAS]] -> 195 | T19: SI | U19: 0 | V19: 195 | W19: 0 | X19: 0 | Z19: =SUM(Tabla1[[#This Row],[RES-A]:[EXTR-B]]) -> 195 | AA19: =Tabla1[[#This Row],[Columna1]]-Tabla1[[#This Row],[IMPORTE TOTAL]] -> 0
A20: 2020 | B20: GENER | C20: 43856 | D20: DIUMENGE | E20: NO | F20: NO | G20: 0.64583333 | H20: 0.85416667 | I20: TARDA | J20: 1 | P20: 145 | Q20: 0 | R20: 0 | S20: =Tabla1[[#This Row],[TARIFA]]+Tabla1[[#This Row],[IMPORTE EXTRAS]] -> 145 | T20: SI | U20: 50 | V20: 95 | W20: 0 | X20: 0 | Z20: =SUM(Tabla1[[#This Row],[RES-A]:[EXTR-B]]) -> 145 | AA20: =Tabla1[[#This Row],[Columna1]]-Tabla1[[#This Row],[IMPORTE TOTAL]] -> 0
A21: 2020 | B21: GENER | C21: 43861 | D21: DIVENDRES | E21: NO | F21: NO | G21: 0.64583333 | H21: 0.85416667 | I21: TARDA | J21: 1 | P21: 135 | Q21: 0 | R21: 0 | S21: =Tabla1[[#This Row],[TARIFA]]+Tabla1[[#This Row],[IMPORTE EXTRAS]] -> 135 | T21: SI | U21: 0 | V21: 135 | W21: 0 | X21: 0 | Z21: =SUM(Tabla1[[#This Row],[RES-A]:[EXTR-B]]) -> 135 | AA21: =Tabla1[[#This Row],[Columna1]]-Tabla1[[#This Row],[IMPORTE TOTAL]] -> 0
A22: 2020 | B22: GENER | C22: 43861 | D22: DIVENDRES | E22: NO | F22: NO | G22: 0.89583333 | H22: 0.10416667 | I22: NIT | J22: 1 | P22: 195 | Q22: 0 | R22: 0 | S22: =Tabla1[[#This Row],[TARIFA]]+Tabla1[[#This Row],[IMPORTE EXTRAS]] -> 195 | T22: SI | U22: 50 | V22: 145 | W22: 0 | X22: 0 | Z22: =SUM(Tabla1[[#This Row],[RES-A]:[EXTR-B]]) -> 195 | AA22: =Tabla1[[#This Row],[Columna1]]-Tabla1[[#This Row],[IMPORTE TOTAL]] -> 0
... A34: 2020 | B34: FEBRER | C34: 43883 | D34: DISSABTE | E34: NO | F34: NO | G34: 0.64583333 | H34: 0.85416667 | I34: TARDA | J34: 1 | P34: 145 | Q34: 1 | R34: 5 | S34: =Tabla1[[#This Row],[TARIFA]]+Tabla1[[#This Row],[IMPORTE EXTRAS]] -> 150 | T34: SI | U34: 0 | V34: 145 | W34: 0 | X34: 5 | Z34: =SUM(Tabla1[[#This Row],[RES-A]:[EXTR-B]]) -> 150 | AA34: =Tabla1[[#This Row],[Columna1]]-Tabla1[[#This Row],[IMPORTE TOTAL]] -> 0
A35: 2020 | B35: FEBRER | C35: 43883 | D35: DISSABTE | E35: NO | F35: NO | G35: 0.89583333 | H35: 0.10416667 | I35: NIT | J35: 1 | P35: 195 | Q35: 1 | R35: 5 | S35: =Tabla1[[#This Row],[TARIFA]]+Tabla1[[#This Row],[IMPORTE EXTRAS]] -> 200 | T35: SI | U35: 0 | V35: 195 | W35: 0 | X35: 5 | Y35: ANUAL | Z35: =SUM(Tabla1[[#This Row],[RES-A]:[EXTR-B]]) -> 200 | AA35: =Tabla1[[#This Row],[Columna1]]-Tabla1[[#This Row],[IMPORTE TOTAL]] -> 0
A36: 2020 | B36: FEBRER | C36: 43884 | D36: DIUMENGE | E36: NO | F36: NO | G36: 0.39583333 | H36: 0.60416667 | I36: MATI | J36: 1 | P36: 145 | Q36: 0 | R36: 0 | S36: =Tabla1[[#This Row],[TARIFA]]+Tabla1[[#This Row],[IMPORTE EXTRAS]] -> 145 | T36: SI | U36: 145 | V36: 0 | W36: 0 | X36: 0 | Z36: =SUM(Tabla1[[#This Row],[RES-A]:[EXTR-B]]) -> 145 | AA36: =Tabla1[[#This Row],[Columna1]]-Tabla1[[#This Row],[IMPORTE TOTAL]] -> 0
A37: 2020 | B37: FEBRER | C37: 43884 | D37: DIUMENGE | E37: NO | F37: NO | G37: 0.85416667 | H37: 0.10416667 | I37: NIT | J37: 1 | P37: 195 | Q37: 0 | R37: 0 | S37: =Tabla1[[#This Row],[TARIFA]]+Tabla1[[#This Row],[IMPORTE EXTRAS]] -> 195 | T37: SI | U37: 100 | V37: 95 | W37: 0 | X37: 0 | Z37: =SUM(Tabla1[[#This Row],[RES-A]:[EXTR-B]]) -> 195 | AA37: =Tabla1[[#This Row],[Columna1]]-Tabla1[[#This Row],[IMPORTE TOTAL]] -> 0
A38: 2020 | B38: FEBRER | C38: 43885 | D38: DILLUNS | E38: NO | F38: NO | G38: 0.64583333 | H38: 0.85416667 | I38: TARDA | J38: 1 | P38: 95 | Q38: 0 | R38: 0 | S38: =Tabla1[[#This Row],[TARIFA]]+Tabla1[[#This Row],[IMPORTE EXTRAS]] -> 95 | T38: SI | U38: 50 | V38: 45 | W38: 0 | X38: 0 | Z38: =SUM(Tabla1[[#This Row],[RES-A]:[EXTR-B]]) -> 95 | AA38: =Tabla1[[#This Row],[Columna1]]-Tabla1[[#This Row],[IMPORTE TOTAL]] -> 0
A39: 2020 | B39: FEBRER | C39: 43890 | D39: DISSABTE | E39: NO | F39: NO | G39: 0.39583333 | H39: 0.60416667 | I39: MATI | J39: 1 | P39: 145 | Q39: 0 | R39: 0 | S39: =Tabla1[[#This Row],[TARIFA]]+Tabla1[[#This Row],[IMPORTE EXTRAS]] -> 145 | T39: SI | U39: 50 | V39: 95 | W39: 0 | X39: 0 | Z39: =SUM(Tabla1[[#This Row],[RES-A]:[EXTR-B]]) -> 145 | AA39: =Tabla1[[#This Row],[Columna1]]-Tabla1[[#This Row],[IMPORTE TOTAL]] -> 0
A40: 2020 | B40: FEBRER | C40: 43890 | D40: DISSABTE | E40: NO | F40: NO | G40: 0.64583333 | H40: 0.85416667 | I40: TARDA | J40: 1 | P40: 145 | Q40: 0 | R40: 0 | S40: =Tabla1[[#This Row],[TARIFA]]+Tabla1[[#This Row],[IMPORTE EXTRAS]] -> 145 | T40: SI | U40: 50 | V40: 95 | W40: 0 | X40: 0 | Z40: =SUM(Tabla1[[#This Row],[RES-A]:[EXTR-B]]) -> 145 | AA40: =Tabla1[[#This Row],[Columna1]]-Tabla1[[#This Row],[IMPORTE TOTAL]] -> 0
A41: 2020 | B41: FEBRER | C41: 43890 | D41: DISSABTE | E41: NO | F41: NO | G41: 0.89583333 | H41: 0.10416667 | I41: NIT | J41: 1 | P41: 195 | Q41: 0 | R41: 0 | S41: =Tabla1[[#This Row],[TARIFA]]+Tabla1[[#This Row],[IMPORTE EXTRAS]] -> 195 | T41: SI | U41: 195 | V41: 0 | W41: 0 | X41: 0 | Z41: =SUM(Tabla1[[#This Row],[RES-A]:[EXTR-B]]) -> 195 | AA41: =Tabla1[[#This Row],[Columna1]]-Tabla1[[#This Row],[IMPORTE TOTAL]] -> 0
A42: 2020 | B42: MARÇ | C42: 43896 | D42: DIVENDRES | E42: NO | F42: NO | G42: 0.89583333 | H42: 0.10416667 | I42: NIT | J42: 1 | P42: 195 | Q42: 1 | R42: 50 | S42: =Tabla1[[#This Row],[TARIFA]]+Tabla1[[#This Row],[IMPORTE EXTRAS]] -> 245 | T42: SI | U42: 50 | V42: 145 | W42: 0 | X42: 50 | Z42: =SUM(Tabla1[[#This Row],[RES-A]:[EXTR-B]]) -> 245 | AA42: =Tabla1[[#This Row],[Columna1]]-Tabla1[[#This Row],[IMPORTE TOTAL]] -> 0
A43: 2020 | B43: MARÇ | C43: 43897 | D43: DISSABTE | E43: NO | F43: NO | G43: 0.625 | H43: 0.85416667 | I43: TARDA | J43: 1 | P43: 145 | Q43: 0 | R43: 0 | S43: =Tabla1[[#This Row],[TARIFA]]+Tabla1[[#This Row],[IMPORTE EXTRAS]] -> 145 | T43: SI | U43: 50 | V43: 95 | W43: 0 | X43: 0 | Z43: =SUM(Tabla1[[#This Row],[RES-A]:[EXTR-B]]) -> 145 | AA43: =Tabla1[[#This Row],[Columna1]]-Tabla1[[#This Row],[IMPORTE TOTAL]] -> 0
A44: 2020 | B44: MARÇ | C44: 43898 | D44: DIUMENGE | E44: NO | F44: NO | G44: 0.39583333 | H44: 0.60416667 | I44: MATI | J44: 1 | P44: 145 | Q44: 0 | R44: 0 | S44: =Tabla1[[#This Row],[TARIFA]]+Tabla1[[#This Row],[IMPORTE EXTRAS]] -> 145 | T44: SI | U44: 50 | V44: 95 | W44: 0 | X44: 0 | Z44: =SUM(Tabla1[[#This Row],[RES-A]:[EXTR-B]]) -> 145 | AA44: =Tabla1[[#This Row],[Columna1]]-Tabla1[[#This Row],[IMPORTE TOTAL]] -> 0
A45: 2020 | B45: MARÇ | C45: 43898 | D45: DIUMENGE | E45: NO | F45: NO | G45: 0.625 | H45: 0.85416667 | I45: TARDA | J45: 1 | P45: 145 | Q45: 1 | R45: 20 | S45: =Tabla1[[#This Row],[TARIFA]]+Tabla1[[#This Row],[IMPORTE EXTRAS]] -> 165 | T45: SI | U45: 50 | V45: 95 | W45: 0 | X45: 20 | Z45: =SUM(Tabla1[[#This Row],[RES-A]:[EXTR-B]]) -> 165 | AA45: =Tabla1[[#This Row],[Columna1]]-Tabla1[[#This Row],[IMPORTE TOTAL]] -> 0
A46: 2020 | B46: MARÇ | C46: 43903 | D46: DIVENDRES | E46: NO | F46: NO | G46: 0.625 | H46: 0.85416667 | I46: TARDA | J46: 1 | P46: 135 | Q46: 0 | R46: 0 | S46: =Tabla1[[#This Row],[TARIFA]]+Tabla1[[#This Row],[IMPORTE EXTRAS]] -> 135 | T46: RESERVA | U46: 0 | V46: 0 | W46: 0 | X46: 0 | Y46: ANULAT | Z46: =SUM(Tabla1[[#This Row],[RES-A]:[EXTR-B]]) -> 0 | AA46: =Tabla1[[#This Row],[Columna1]]-Tabla1[[#This Row],[IMPORTE TOTAL]] -> -135
A47: 2020 | B47: MARÇ | C47: 43903 | D47: DIVENDRES | E47: NO | F47: NO | G47: 0.89583333 | H47: 0.10416667 | I47: NIT | J47: 1 | P47: 195 | Q47: 0 | R47: 0 | S47: =Tabla1[[#This Row],[TARIFA]]+Tabla1[[#This Row],[IMPORTE EXTRAS]] -> 195 | T47: RESERVA | U47: 0 | V47: 0 | W47: 0 | X47: 0 | Y47: ANULAT | Z47: =SUM(Tabla1[[#This Row],[RES-A]:[EXTR-B]]) -> 0 | AA47: =Tabla1[[#This Row],[Columna1]]-Tabla1[[#This Row],[IMPORTE TOTAL]] -> -195
A48: 2020 | B48: MARÇ | C48: 43904 | D48: DISSABTE | E48: NO | F48: NO | G48: 0.39583333 | H48: 0.85416667 | I48: DIA SENCER | J48: 2 | P48: 270 | Q48: 0 | R48: 0 | S48: =Tabla1[[#This Row],[TARIFA]]+Tabla1[[#This Row],[IMPORTE EXTRAS]] -> 270 | T48: RESERVA | U48: 0 | V48: 0 | W48: 0 | X48: 0 | Y48: ANULAT | Z48: =SUM(Tabla1[[#This Row],[RES-A]:[EXTR-B]]) -> 0 | AA48: =Tabla1[[#This Row],[Columna1]]-Tabla1[[#This Row],[IMPORTE TOTAL]] -> -270
A49: 2020 | B49: MARÇ | C49: 43904 | D49: DISSABTE | E49: NO | F49: NO | G49: 0.89583333 | H49: 0.10416667 | I49: NIT | J49: 1 | P49: 195 | Q49: 0 | R49: 0 | S49: =Tabla1[[#This Row],[TARIFA]]+Tabla1[[#This Row],[IMPORTE EXTRAS]] -> 195 | T49: RESERVA | U49: 0 | V49: 0 | W49: 0 | X49: 0 | Y49: APLAÇAT | Z49: =SUM(Tabla1[[#This Row],[RES-A]:[EXTR-B]]) -> 0 | AA49: =Tabla1[[#This Row],[Columna1]]-Tabla1[[#This Row],[IMPORTE TOTAL]] -> -195
A50: 2020 | B50: MARÇ | C50: 43905 | D50: DIUMENGE | E50: NO | F50: NO | G50: 0.39583333 | H50: 0.85416667 | I50: DIA SENCER | J50: 2 | P50: 270 | Q50: 0 | R50: 0 | S50: =Tabla1[[#This Row],[TARIFA]]+Tabla1[[#This Row],[IMPORTE EXTRAS]] -> 270 | T50: RESERVA | U50: 0 | V50: 0 | W50: 0 | X50: 0 | Y50: ANULAT | Z50: =SUM(Tabla1[[#This Row],[RES-A]:[EXTR-B]]) -> 0 | AA50: =Tabla1[[#This Row],[Columna1]]-Tabla1[[#This Row],[IMPORTE TOTAL]] -> -270
A51: 2020 | B51: MARÇ | C51: 43910 | D51: DIVENDRES | E51: NO | F51: NO | G51: 0.89583333 | H51: 0.10416667 | I51: NIT | J51: 1 | P51: 195 | Q51: 0 | R51: 0 | S51: =Tabla1[[#This Row],[TARIFA]]+Tabla1[[#This Row],[IMPORTE EXTRAS]] -> 195 | T51: RESERVA | U51: 0 | V51: 0 | W51: 0 | X51: 0 | Y51: APLAÇAT | Z51: =SUM(Tabla1[[#This Row],[RES-A]:[EXTR-B]]) -> 0 | AA51: =Tabla1[[#This Row],[Columna1]]-Tabla1[[#This Row],[IMPORTE TOTAL]] -> -195
...

Sheet Registre de despeses
A1: ANY | B1: MES | C1: DATA | D1: TIPUS | E1: TIPO DESPESA | F1: CONCEPTE | G1: IMPORT | H1: A | I1: B | J1: FACTURA TRIMESTRE
A2: 2020 | B2: GENER | C2: 43832 | D2: PÀGINA WEB | E2: =VLOOKUP(Tabla2[[#This Row],[TIPUS]],Tarifas!$H$12:$I$26,2,0) -> FIX | F2: Anualitat Pàgina web - 2 anys | G2: 499 | H2: 499 | I2: 0
A3: 2020 | B3: GENER | C3: 43837 | D3: ASSEGURANÇA | E3: =VLOOKUP(Tabla2[[#This Row],[TIPUS]],Tarifas!$H$12:$I$26,2,0) -> FIX | F3: Rebut anual assegurança | G3: 362.22 | H3: 362.22 | I3: 0
A4: 2020 | B4: GENER | C4: 43840 | D4: CONSUMIBLES | E4: =VLOOKUP(Tabla2[[#This Row],[TIPUS]],Tarifas!$H$12:$I$26,2,0) -> VARIABLE | F4: Productes de neteja | G4: 36.03 | H4: 36.03 | I4: 0
A5: 2020 | B5: GENER | C5: 43842 | D5: PÀGINA WEB | E5: =VLOOKUP(Tabla2[[#This Row],[TIPUS]],Tarifas!$H$12:$I$26,2,0) -> FIX | F5: Logo | G5: 250 | H5: 0 | I5: 250
A6: 2020 | B6: GENER | C6: 43848 | D6: MAQUINARIA | E6: =VLOOKUP(Tabla2[[#This Row],[TIPUS]],Tarifas!$H$12:$I$26,2,0) -> VARIABLE | F6: Arreglo porta lavabo | G6: 35 | H6: 0 | I6: 35
A7: 2020 | B7: GENER | C7: 43849 | D7: LLOGUER | E7: =VLOOKUP(Tabla2[[#This Row],[TIPUS]],Tarifas!$H$12:$I$26,2,0) -> FIX | F7: Lloguer gener 2020 | G7: 506 | H7: 306 | I7: 200
A8: 2020 | B8: GENER | C8: 43857 | D8: MAQUINARIA | E8: =VLOOKUP(Tabla2[[#This Row],[TIPUS]],Tarifas!$H$12:$I$26,2,0) -> VARIABLE | F8: Arreglo porta principal | G8: 45 | H8: 0 | I8: 45
A9: 2020 | B9: GENER | C9: 43858 | D9: LLOGUER | E9: =VLOOKUP(Tabla2[[#This Row],[TIPUS]],Tarifas!$H$12:$I$26,2,0) -> FIX | F9: INCASOL | G9: 600 | H9: 600 | I9: 0
A10: 2020 | B10: GENER | C10: 43859 | D10: INVERSIONS CAPITAL | E10: =VLOOKUP(Tabla2[[#This Row],[TIPUS]],Tarifas!$H$12:$I$26,2,0) -> INVERSIONS | F10: Nevera | G10: 377 | H10: 377 | I10: 0
A11: 2020 | B11: GENER | C11: 43860 | D11: CONSUMIBLES | E11: =VLOOKUP(Tabla2[[#This Row],[TIPUS]],Tarifas!$H$12:$I$26,2,0) -> VARIABLE | F11: Flyers | G11: 64 | H11: 0 | I11: 64
A12: 2020 | B12: GENER | C12: 43861 | D12: AUTÒNOM | E12: =VLOOKUP(Tabla2[[#This Row],[TIPUS]],Tarifas!$H$12:$I$26,2,0) -> FIX | F12: Qutoa Gener 2020 | G12: 67.54 | H12: 67.54 | I12: 0
A13: 2020 | B13: GENER | C13: 43861 | D13: TELÈFON | E13: =VLOOKUP(Tabla2[[#This Row],[TIPUS]],Tarifas!$H$12:$I$26,2,0) -> FIX | F13: Quota Gener 2020 | G13: 25 | H13: 25 | I13: 0
A14: 2020 | B14: GENER | C14: 43861 | D14: EXTERNALITZACIÓ NETEJA | E14: =VLOOKUP(Tabla2[[#This Row],[TIPUS]],Tarifas!$H$12:$I$26,2,0) -> VARIABLE | F14: Netejes Gener 2020 | G14: 150 | H14: 0 | I14: 150
A15: 2020 | B15: GENER | C15: 43861 | D15: LLUM | E15: =VLOOKUP(Tabla2[[#This Row],[TIPUS]],Tarifas!$H$12:$I$26,2,0) -> VARIABLE | F15: Quota Gener 2020 | G15: =54.32/2 -> 27.16 | H15: =54.32/2 -> 27.16 | I15: 0
A16: 2020 | B16: FEBRER | C16: 43878 | D16: LLOGUER | E16: =VLOOKUP(Tabla2[[#This Row],[TIPUS]],Tarifas!$H$12:$I$26,2,0) -> FIX | F16: Lloguer febrer 2020 | G16: 506 | H16: 306 | I16: 200
A17: 2020 | B17: FEBRER | C17: 43879 | D17: CONSUMIBLES | E17: =VLOOKUP(Tabla2[[#This Row],[TIPUS]],Tarifas!$H$12:$I$26,2,0) -> VARIABLE | F17: Lampara projector | G17: 90 | H17: 0 | I17: 90
A18: 2020 | B18: FEBRER | C18: 43880 | D18: EXTERNALITZACIÓ NETEJA | E18: =VLOOKUP(Tabla2[[#This Row],[TIPUS]],Tarifas!$H$12:$I$26,2,0) -> VARIABLE | F18: Ania febrer | G18: 120 | H18: 0 | I18: 120
A19: 2020 | B19: FEBRER | C19: 43883 | D19: EXTERNALITZACIÓ NETEJA | E19: =VLOOKUP(Tabla2[[#This Row],[TIPUS]],Tarifas!$H$12:$I$26,2,0) -> VARIABLE | F19: Netejes Febrer 2020 | G19: 175 | H19: 0 | I19: 175
A20: 2020 | B20: FEBRER | C20: 43883 | D20: INVERSIONS CAPITAL | E20: =VLOOKUP(Tabla2[[#This Row],[TIPUS]],Tarifas!$H$12:$I$26,2,0) -> INVERSIONS | F20: Taules Leroy Merlin | G20: 131.53 | H20: 131.53 | I20: 0
A21: 2020 | B21: FEBRER | C21: 43883 | D21: CONSUMIBLES | E21: =VLOOKUP(Tabla2[[#This Row],[TIPUS]],Tarifas!$H$12:$I$26,2,0) -> VARIABLE | F21: Draps Ikea | G21: 3 | H21: 3 | I21: 0
A22: 2020 | B22: FEBRER | C22: 43883 | D22: INVERSIONS CAPITAL | E22: =VLOOKUP(Tabla2[[#This Row],[TIPUS]],Tarifas!$H$12:$I$26,2,0) -> INVERSIONS | F22: Secamans Amazon | G22: 40.06 | H22: 40.06 | I22: 0
A23: 2020 | B23: FEBRER | C23: 43889 | D23: AUTÒNOM | E23: =VLOOKUP(Tabla2[[#This Row],[TIPUS]],Tarifas!$H$12:$I$26,2,0) -> FIX | F23: Quota Febrer 2020 | G23: 67.54 | H23: 67.54 | I23: 0
A24: 2020 | B24: FEBRER | C24: 43889 | D24: TELÈFON | E24: =VLOOKUP(Tabla2[[#This Row],[TIPUS]],Tarifas!$H$12:$I$26,2,0) -> FIX | F24: Quota Febrer 2020 | G24: 53.8 | H24: 53.8 | I24: 0
A25: 2020 | B25: FEBRER | C25: 43889 | D25: LLUM | E25: =VLOOKUP(Tabla2[[#This Row],[TIPUS]],Tarifas!$H$12:$I$26,2,0) -> VARIABLE | F25: Quota Febrer 2020 | G25: =54.32/2 -> 27.16 | H25: =54.32/2 -> 27.16 | I25: 0
A26: 2020 | B26: MARÇ | C26: 43896 | D26: LLOGUER | E26: =VLOOKUP(Tabla2[[#This Row],[TIPUS]],Tarifas!$H$12:$I$26,2,0) -> FIX | F26: Lloguer març 2020 | G26: 506 | H26: 306 | I26: 200
A27: 2020 | B27: MARÇ | C27: 43899 | D27: CONSUMIBLES | E27: =VLOOKUP(Tabla2[[#This Row],[TIPUS]],Tarifas!$H$12:$I$26,2,0) -> VARIABLE | F27: Pintures pel trono | G27: 18.61 | H27: 18.61 | I27: 0
A28: 2020 | B28: ABRIL | C28: 43931 | D28: TELÈFON | E28: =VLOOKUP(Tabla2[[#This Row],[TIPUS]],Tarifas!$H$12:$I$26,2,0) -> FIX | F28: Quota Abril 2020 | G28: 55.34 | H28: 55.34 | I28: 0
A29: 2020 | B29: MARÇ | C29: 43921 | D29: AUTÒNOM | E29: =VLOOKUP(Tabla2[[#This Row],[TIPUS]],Tarifas!$H$12:$I$26,2,0) -> FIX | F29: Quota Març 2020 | G29: =67.54-38.5 -> 29.04 | H29: =67.54-38.5 -> 29.04 | I29: 0 | K29: HI HA UN RETORN DE 38,50
A30: 2020 | B30: MAIG | C30: 43955 | D30: TELÈFON | E30: =VLOOKUP(Tabla2[[#This Row],[TIPUS]],Tarifas!$H$12:$I$26,2,0) -> FIX | F30: Quota Maig 2020 | G30: 57 | H30: 57 | I30: 0
A31: 2020 | B31: MAIG | C31: 43956 | D31: CONSUMIBLES | E31: =VLOOKUP(Tabla2[[#This Row],[TIPUS]],Tarifas!$H$12:$I$26,2,0) -> VARIABLE | F31: Revisió extintors | G31: 50.92 | H31: 0 | I31: 50.92
A32: 2020 | B32: MAIG | C32: 43956 | D32: CONSUMIBLES | E32: =VLOOKUP(Tabla2[[#This Row],[TIPUS]],Tarifas!$H$12:$I$26,2,0) -> VARIABLE | F32: Pintures de la sala | G32: 0 | H32: 0 | I32: 0 | K32: 199.86
A33: 2020 | B33: MAIG | C33: 43956 | D33: CONSUMIBLES | E33: =VLOOKUP(Tabla2[[#This Row],[TIPUS]],Tarifas!$H$12:$I$26,2,0) -> VARIABLE | F33: Pintures de la sala | G33: 36.23 | H33: 0 | I33: 36.23
A34: 2020 | B34: MAIG | C34: 43966 | D34: CONSUMIBLES | E34: =VLOOKUP(Tabla2[[#This Row],[TIPUS]],Tarifas!$H$12:$I$26,2,0) -> VARIABLE | F34: Rètols | G34: 100 | H34: 0 | I34: 100
A35: 2020 | B35: MAIG | C35: 43976 | D35: GESTORÍA | E35: =VLOOKUP(Tabla2[[#This Row],[TIPUS]],Tarifas!$H$12:$I$26,2,0) -> FIX | F35: Primer trimestre | G35: 90 | H35: 0 | I35: 90
A36: 2020 | B36: MAIG | C36: 43976 | D36: IMPOSTOS | E36: =VLOOKUP(Tabla2[[#This Row],[TIPUS]],Tarifas!$H$12:$I$26,2,0) -> IMPOSTOS | F36: Primer trimestre IVA i IRPF | G36: =230.93+1.62+171 -> 403.55 | H36: =230.93+1.62+171 -> 403.55 | I36: 0
A37: 2020 | B37: JUNY | C37: 43986 | D37: TELÈFON | E37: =VLOOKUP(Tabla2[[#This Row],[TIPUS]],Tarifas!$H$12:$I$26,2,0) -> FIX | F37: Quota Juny 2020 | G37: 57 | H37: 57 | I37: 0
A38: 2020 | B38: JUNY | C38: 43991 | D38: CONSUMIBLES | E38: =VLOOKUP(Tabla2[[#This Row],[TIPUS]],Tarifas!$H$12:$I$26,2,0) -> VARIABLE | F38: Rètols | G38: 125 | H38: 0 | I38: 125
A39: 2020 | B39: JUNY | C39: 44012 | D39: CONSUMIBLES | E39: =VLOOKUP(Tabla2[[#This Row],[TIPUS]],Tarifas!$H$12:$I$26,2,0) -> VARIABLE | F39: Leroy Merlin | G39: 19.08 | H39: 19.08 | I39: 0
A40: 2020 | B40: JUNY | C40: 44012 | D40: LLOGUER | E40: =VLOOKUP(Tabla2[[#This Row],[TIPUS]],Tarifas!$H$12:$I$26,2,0) -> FIX | F40: Lloguer juny 2020 | G40: 152 | H40: 0 | I40: 152
...

Sheet 2025
A2: 6 | B2: GENER | D2: FEBRER | F2: MARÇ | H2: ABRIL | J2: MAIG | L2: JUNY | N2: JULIOL | P2: AGOST | R2: SETEMBRE | T2: OCTUBRE | V2: NOVEMBRE | X2: DESEMBRE | Z2: 2025 | AB2: MITJA ANUAL
A3: INGRESOS | B3: =B4+B22 -> 4865 | C3: =IF(B3=0,0,(B3/B3)) -> 1 | D3: =D4+D22 -> 3665 | E3: =IF(D3=0,0,(D3/D3)) -> 1 | F3: =F4+F22 -> 3975 | G3: =IF(F3=0,0,(F3/F3)) -> 1 | H3: =H4+H22 -> 3265 | I3: =IF(H3=0,0,(H3/H3)) -> 1 | J3: =J4+J22 -> 3780 | K3: =IF(J3=0,0,(J3/J3)) -> 1 | L3: =L4+L22 -> 3420 | M3: =IF(L3=0,0,(L3/L3)) -> 1 | N3: =N4+N22 -> 0 | O3: =IF(N3=0,0,(N3/N3)) -> 0 | P3: =P4+P22 -> 0 | Q3: =IF(P3=0,0,(P3/P3)) -> 0 | R3: =R4+R22 -> 0 | S3: =IF(R3=0,0,(R3/R3)) -> 0 | T3: =T4+T22 -> 0 | U3: =IF(T3=0,0,(T3/T3)) -> 0 | V3: =V4+V22 -> 0 | W3: =IF(V3=0,0,(V3/V3)) -> 0 | X3: =X4+X22 -> 0 | Y3: =IF(X3=0,0,(X3/X3)) -> 0 | Z3: =Z4+Z22 -> 22970 | AA3: =IF(Z3=0,0,(Z3/Z3)) -> 1 | AB3: =Z3/$A$2 -> 3828.3333
A4: Reserves efectives | B4: =SUM(B5:B12) -> 4565 | C4: =IF(B$3=0,0,B4/B$3) -> 0.93833505 | D4: =SUM(D5:D12) -> 3585 | E4: =IF(D$3=0,0,D4/D$3) -> 0.9781719 | F4: =SUM(F5:F12) -> 3975 | G4: =IF(F$3=0,0,F4/F$3) -> 1 | H4: =SUM(H5:H12) -> 3085 | I4: =IF(H$3=0,0,H4/H$3) -> 0.94486983 | J4: =SUM(J5:J12) -> 3690 | K4: =IF(J$3=0,0,J4/J$3) -> 0.97619048 | L4: =SUM(L5:L12) -> 3360 | M4: =IF(L$3=0,0,L4/L$3) -> 0.98245614 | N4: =SUM(N5:N12) -> 0 | O4: =IF(N$3=0,0,N4/N$3) -> 0 | P4: =SUM(P5:P12) -> 0 | Q4: =IF(P$3=0,0,P4/P$3) -> 0 | R4: =SUM(R5:R12) -> 0 | S4: =IF(R$3=0,0,R4/R$3) -> 0 | T4: =SUM(T5:T12) -> 0 | U4: =IF(T$3=0,0,T4/T$3) -> 0 | V4: =SUM(V5:V12) -> 0 | W4: =IF(V$3=0,0,V4/V$3) -> 0 | X4: =SUM(X5:X12) -> 0 | Y4: =IF(X$3=0,0,X4/X$3) -> 0 | Z4: =SUM(Z5:Z12) -> 22260 | AA4: =IF(Z$3=0,0,Z4/Z$3) -> 0.96909012 | AB4: =Z4/$A$2 -> 3710
A5: Mati | B5: =SUMIFS('Registre de reserves'!$P$2:$P$1178,'Registre de reserves'!$T$2:$T$1178,"SI",'Registre de reserves'!$I$2:$I$1178,'2025'!$A5,'Registre de reserves'!$B$2:$B$1178,'2025'!B$2,Tabla1[ANY],'2025'!$Z$2)+SUMIFS('Registre de reserves'!$U$2:$U$1178,'Registre de reserves'!$T$2:$T$1178,"RESERVA",'Registre de reserves'!$I$2:$I$1178,'2025'!$A5,'Registre de reserves'!$B$2:$B$1178,'2025'!B$2,Tabla1[ANY],'2025'!$Z$2) -> 600 | C5: =IF(B$4=0,0,B5/B$4) -> 0.13143483 | D5: =SUMIFS('Registre de reserves'!$P$2:$P$1178,'Registre de reserves'!$T$2:$T$1178,"SI",'Registre de reserves'!$I$2:$I$1178,'2025'!$A5,'Registre de reserves'!$B$2:$B$1178,'2025'!D$2,Tabla1[ANY],'2025'!$Z$2)+SUMIFS('Registre de reserves'!$U$2:$U$1178,'Registre de reserves'!$T$2:$T$1178,"RESERVA",'Registre de reserves'!$I$2:$I$1178,'2025'!$A5,'Registre de reserves'!$B$2:$B$1178,'2025'!D$2,Tabla1[ANY],'2025'!$Z$2) -> 1050 | E5: =IF(D$4=0,0,D5/D$4) -> 0.29288703 | F5: =SUMIFS('Registre de reserves'!$P$2:$P$1178,'Registre de reserves'!$T$2:$T$1178,"SI",'Registre de reserves'!$I$2:$I$1178,'2025'!$A5,'Registre de reserves'!$B$2:$B$1178,'2025'!F$2,Tabla1[ANY],'2025'!$Z$2)+SUMIFS('Registre de reserves'!$U$2:$U$1178,'Registre de reserves'!$T$2:$T$1178,"RESERVA",'Registre de reserves'!$I$2:$I$1178,'2025'!$A5,'Registre de reserves'!$B$2:$B$1178,'2025'!F$2,Tabla1[ANY],'2025'!$Z$2) -> 750 | G5: =IF(F$4=0,0,F5/F$4) -> 0.18867925 | H5: =SUMIFS('Registre de reserves'!$P$2:$P$1178,'Registre de reserves'!$T$2:$T$1178,"SI",'Registre de reserves'!$I$2:$I$1178,'2025'!$A5,'Registre de reserves'!$B$2:$B$1178,'2025'!H$2,Tabla1[ANY],'2025'!$Z$2)+SUMIFS('Registre de reserves'!$U$2:$U$1178,'Registre de reserves'!$T$2:$T$1178,"RESERVA",'Registre de reserves'!$I$2:$I$1178,'2025'!$A5,'Registre de reserves'!$B$2:$B$1178,'2025'!H$2,Tabla1[ANY],'2025'!$Z$2) -> 900 | I5: =IF(H$4=0,0,H5/H$4) -> 0.2917342 | J5: =SUMIFS('Registre de reserves'!$P$2:$P$1178,'Registre de reserves'!$T$2:$T$1178,"SI",'Registre de reserves'!$I$2:$I$1178,'2025'!$A5,'Registre de reserves'!$B$2:$B$1178,'2025'!J$2,Tabla1[ANY],'2025'!$Z$2)+SUMIFS('Registre de reserves'!$U$2:$U$1178,'Registre de reserves'!$T$2:$T$1178,"RESERVA",'Registre de reserves'!$I$2:$I$1178,'2025'!$A5,'Registre de reserves'!$B$2:$B$1178,'2025'!J$2,Tabla1[ANY],'2025'!$Z$2) -> 750 | K5: =IF(J$4=0,0,J5/J$4) -> 0.20325203 | L5: =SUMIFS('Registre de reserves'!$P$2:$P$1178,'Registre de reserves'!$T$2:$T$1178,"SI",'Registre de reserves'!$I$2:$I$1178,'2025'!$A5,'Registre de reserves'!$B$2:$B$1178,'2025'!L$2,Tabla1[ANY],'2025'!$Z$2)+SUMIFS('Registre de reserves'!$U$2:$U$1178,'Registre de reserves'!$T$2:$T$1178,"RESERVA",'Registre de reserves'!$I$2:$I$1178,'2025'!$A5,'Registre de reserves'!$B$2:$B$1178,'2025'!L$2,Tabla1[ANY],'2025'!$Z$2) -> 450 | M5: =IF(L$4=0,0,L5/L$4) -> 0.13392857 | N5: =SUMIFS('Registre de reserves'!$P$2:$P$1178,'Registre de reserves'!$T$2:$T$1178,"SI",'Registre de reserves'!$I$2:$I$1178,'2025'!$A5,'Registre de reserves'!$B$2:$B$1178,'2025'!N$2,Tabla1[ANY],'2025'!$Z$2)+SUMIFS('Registre de reserves'!$U$2:$U$1178,'Registre de reserves'!$T$2:$T$1178,"RESERVA",'Registre de reserves'!$I$2:$I$1178,'2025'!$A5,'Registre de reserves'!$B$2:$B$1178,'2025'!N$2,Tabla1[ANY],'2025'!$Z$2) -> 0 | O5: =IF(N$4=0,0,N5/N$4) -> 0 | P5: =SUMIFS('Registre de reserves'!$P$2:$P$1178,'Registre de reserves'!$T$2:$T$1178,"SI",'Registre de reserves'!$I$2:$I$1178,'2025'!$A5,'Registre de reserves'!$B$2:$B$1178,'2025'!P$2,Tabla1[ANY],'2025'!$Z$2)+SUMIFS('Registre de reserves'!$U$2:$U$1178,'Registre de reserves'!$T$2:$T$1178,"RESERVA",'Registre de reserves'!$I$2:$I$1178,'2025'!$A5,'Registre de reserves'!$B$2:$B$1178,'2025'!P$2,Tabla1[ANY],'2025'!$Z$2) -> 0 | Q5: =IF(P$4=0,0,P5/P$4) -> 0 | R5: =SUMIFS('Registre de reserves'!$P$2:$P$1178,'Registre de reserves'!$T$2:$T$1178,"SI",'Registre de reserves'!$I$2:$I$1178,'2025'!$A5,'Registre de reserves'!$B$2:$B$1178,'2025'!R$2,Tabla1[ANY],'2025'!$Z$2)+SUMIFS('Registre de reserves'!$U$2:$U$1178,'Registre de reserves'!$T$2:$T$1178,"RESERVA",'Registre de reserves'!$I$2:$I$1178,'2025'!$A5,'Registre de reserves'!$B$2:$B$1178,'2025'!R$2,Tabla1[ANY],'2025'!$Z$2) -> 0 | S5: =IF(R$4=0,0,R5/R$4) -> 0 | T5: =SUMIFS('Registre de reserves'!$P$2:$P$1178,'Registre de reserves'!$T$2:$T$1178,"SI",'Registre de reserves'!$I$2:$I$1178,'2025'!$A5,'Registre de reserves'!$B$2:$B$1178,'2025'!T$2,Tabla1[ANY],'2025'!$Z$2)+SUMIFS('Registre de reserves'!$U$2:$U$1178,'Registre de reserves'!$T$2:$T$1178,"RESERVA",'Registre de reserves'!$I$2:$I$1178,'2025'!$A5,'Registre de reserves'!$B$2:$B$1178,'2025'!T$2,Tabla1[ANY],'2025'!$Z$2) -> 0 | U5: =IF(T$4=0,0,T5/T$4) -> 0 | V5: =SUMIFS('Registre de reserves'!$P$2:$P$1178,'Registre de reserves'!$T$2:$T$1178,"SI",'Registre de reserves'!$I$2:$I$1178,'2025'!$A5,'Registre de reserves'!$B$2:$B$1178,'2025'!V$2,Tabla1[ANY],'2025'!$Z$2)+SUMIFS('Registre de reserves'!$U$2:$U$1178,'Registre de reserves'!$T$2:$T$1178,"RESERVA",'Registre de reserves'!$I$2:$I$1178,'2025'!$A5,'Registre de reserves'!$B$2:$B$1178,'2025'!V$2,Tabla1[ANY],'2025'!$Z$2) -> 0 | W5: =IF(V$4=0,0,V5/V$4) -> 0 | X5: =SUMIFS('Registre de reserves'!$P$2:$P$1178,'Registre de reserves'!$T$2:$T$1178,"SI",'Registre de reserves'!$I$2:$I$1178,'2025'!$A5,'Registre de reserves'!$B$2:$B$1178,'2025'!X$2,Tabla1[ANY],'2025'!$Z$2)+SUMIFS('Registre de reserves'!$U$2:$U$1178,'Registre de reserves'!$T$2:$T$1178,"RESERVA",'Registre de reserves'!$I$2:$I$1178,'2025'!$A5,'Registre de reserves'!$B$2:$B$1178,'2025'!X$2,Tabla1[ANY],'2025'!$Z$2) -> 0 | Y5: =IF(X$4=0,0,X5/X$4) -> 0 | Z5: =B5+D5+F5+H5+J5+L5+N5+P5+R5+T5+V5+X5 -> 4500 | AA5: =IF(Z$4=0,0,Z5/Z$4) -> 0.20215633 | AB5: =Z5/$A$2 -> 750
A6: Tarda | B6: =SUMIFS('Registre de reserves'!$P$2:$P$1178,'Registre de reserves'!$T$2:$T$1178,"SI",'Registre de reserves'!$I$2:$I$1178,'2025'!$A6,'Registre de reserves'!$B$2:$B$1178,'2025'!B$2,Tabla1[ANY],'2025'!$Z$2)+SUMIFS('Registre de reserves'!$U$2:$U$1178,'Registre de reserves'!$T$2:$T$1178,"RESERVA",'Registre de reserves'!$I$2:$I$1178,'2025'!$A6,'Registre de reserves'!$B$2:$B$1178,'2025'!B$2,Tabla1[ANY],'2025'!$Z$2) -> 1855 | C6: =IF(B$4=0,0,B6/B$4) -> 0.40635268 | D6: =SUMIFS('Registre de reserves'!$P$2:$P$1178,'Registre de reserves'!$T$2:$T$1178,"SI",'Registre de reserves'!$I$2:$I$1178,'2025'!$A6,'Registre de reserves'!$B$2:$B$1178,'2025'!D$2,Tabla1[ANY],'2025'!$Z$2)+SUMIFS('Registre de reserves'!$U$2:$U$1178,'Registre de reserves'!$T$2:$T$1178,"RESERVA",'Registre de reserves'!$I$2:$I$1178,'2025'!$A6,'Registre de reserves'!$B$2:$B$1178,'2025'!D$2,Tabla1[ANY],'2025'!$Z$2) -> 1415 | E6: =IF(D$4=0,0,D6/D$4) -> 0.39470014 | F6: =SUMIFS('Registre de reserves'!$P$2:$P$1178,'Registre de reserves'!$T$2:$T$1178,"SI",'Registre de reserves'!$I$2:$I$1178,'2025'!$A6,'Registre de reserves'!$B$2:$B$1178,'2025'!F$2,Tabla1[ANY],'2025'!$Z$2)+SUMIFS('Registre de reserves'!$U$2:$U$1178,'Registre de reserves'!$T$2:$T$1178,"RESERVA",'Registre de reserves'!$I$2:$I$1178,'2025'!$A6,'Registre de reserves'!$B$2:$B$1178,'2025'!F$2,Tabla1[ANY],'2025'!$Z$2) -> 1625 | G6: =IF(F$4=0,0,F6/F$4) -> 0.40880503 | H6: =SUMIFS('Registre de reserves'!$P$2:$P$1178,'Registre de reserves'!$T$2:$T$1178,"SI",'Registre de reserves'!$I$2:$I$1178,'2025'!$A6,'Registre de reserves'!$B$2:$B$1178,'2025'!H$2,Tabla1[ANY],'2025'!$Z$2)+SUMIFS('Registre de reserves'!$U$2:$U$1178,'Registre de reserves'!$T$2:$T$1178,"RESERVA",'Registre de reserves'!$I$2:$I$1178,'2025'!$A6,'Registre de reserves'!$B$2:$B$1178,'2025'!H$2,Tabla1[ANY],'2025'!$Z$2) -> 1185 | I6: =IF(H$4=0,0,H6/H$4) -> 0.38411669 | J6: =SUMIFS('Registre de reserves'!$P$2:$P$1178,'Registre de reserves'!$T$2:$T$1178,"SI",'Registre de reserves'!$I$2:$I$1178,'2025'!$A6,'Registre de reserves'!$B$2:$B$1178,'2025'!J$2,Tabla1[ANY],'2025'!$Z$2)+SUMIFS('Registre de reserves'!$U$2:$U$1178,'Registre de reserves'!$T$2:$T$1178,"RESERVA",'Registre de reserves'!$I$2:$I$1178,'2025'!$A6,'Registre de reserves'!$B$2:$B$1178,'2025'!J$2,Tabla1[ANY],'2025'!$Z$2) -> 1420 | K6: =IF(J$4=0,0,J6/J$4) -> 0.38482385 | L6: =SUMIFS('Registre de reserves'!$P$2:$P$1178,'Registre de reserves'!$T$2:$T$1178,"SI",'Registre de reserves'!$I$2:$I$1178,'2025'!$A6,'Registre de reserves'!$B$2:$B$1178,'2025'!L$2,Tabla1[ANY],'2025'!$Z$2)+SUMIFS('Registre de reserves'!$U$2:$U$1178,'Registre de reserves'!$T$2:$T$1178,"RESERVA",'Registre de reserves'!$I$2:$I$1178,'2025'!$A6,'Registre de reserves'!$B$2:$B$1178,'2025'!L$2,Tabla1[ANY],'2025'!$Z$2) -> 1230 | M6: =IF(L$4=0,0,L6/L$4) -> 0.36607143 | N6: =SUMIFS('Registre de reserves'!$P$2:$P$1178,'Registre de reserves'!$T$2:$T$1178,"SI",'Registre de reserves'!$I$2:$I$1178,'2025'!$A6,'Registre de reserves'!$B$2:$B$1178,'2025'!N$2,Tabla1[ANY],'2025'!$Z$2)+SUMIFS('Registre de reserves'!$U$2:$U$1178,'Registre de reserves'!$T$2:$T$1178,"RESERVA",'Registre de reserves'!$I$2:$I$1178,'2025'!$A6,'Registre de reserves'!$B$2:$B$1178,'2025'!N$2,Tabla1[ANY],'2025'!$Z$2) -> 0 | O6: =IF(N$4=0,0,N6/N$4) -> 0 | P6: =SUMIFS('Registre de reserves'!$P$2:$P$1178,'Registre de reserves'!$T$2:$T$1178,"SI",'Registre de reserves'!$I$2:$I$1178,'2025'!$A6,'Registre de reserves'!$B$2:$B$1178,'2025'!P$2,Tabla1[ANY],'2025'!$Z$2)+SUMIFS('Registre de reserves'!$U$2:$U$1178,'Registre de reserves'!$T$2:$T$1178,"RESERVA",'Registre de reserves'!$I$2:$I$1178,'2025'!$A6,'Registre de reserves'!$B$2:$B$1178,'2025'!P$2,Tabla1[ANY],'2025'!$Z$2) -> 0 | Q6: =IF(P$4=0,0,P6/P$4) -> 0 | R6: =SUMIFS('Registre de reserves'!$P$2:$P$1178,'Registre de reserves'!$T$2:$T$1178,"SI",'Registre de reserves'!$I$2:$I$1178,'2025'!$A6,'Registre de reserves'!$B$2:$B$1178,'2025'!R$2,Tabla1[ANY],'2025'!$Z$2)+SUMIFS('Registre de reserves'!$U$2:$U$1178,'Registre de reserves'!$T$2:$T$1178,"RESERVA",'Registre de reserves'!$I$2:$I$1178,'2025'!$A6,'Registre de reserves'!$B$2:$B$1178,'2025'!R$2,Tabla1[ANY],'2025'!$Z$2) -> 0 | S6: =IF(R$4=0,0,R6/R$4) -> 0 | T6: =SUMIFS('Registre de reserves'!$P$2:$P$1178,'Registre de reserves'!$T$2:$T$1178,"SI",'Registre de reserves'!$I$2:$I$1178,'2025'!$A6,'Registre de reserves'!$B$2:$B$1178,'2025'!T$2,Tabla1[ANY],'2025'!$Z$2)+SUMIFS('Registre de reserves'!$U$2:$U$1178,'Registre de reserves'!$T$2:$T$1178,"RESERVA",'Registre de reserves'!$I$2:$I$1178,'2025'!$A6,'Registre de reserves'!$B$2:$B$1178,'2025'!T$2,Tabla1[ANY],'2025'!$Z$2) -> 0 | U6: =IF(T$4=0,0,T6/T$4) -> 0 | V6: =SUMIFS('Registre de reserves'!$P$2:$P$1178,'Registre de reserves'!$T$2:$T$1178,"SI",'Registre de reserves'!$I$2:$I$1178,'2025'!$A6,'Registre de reserves'!$B$2:$B$1178,'2025'!V$2,Tabla1[ANY],'2025'!$Z$2)+SUMIFS('Registre de reserves'!$U$2:$U$1178,'Registre de reserves'!$T$2:$T$1178,"RESERVA",'Registre de reserves'!$I$2:$I$1178,'2025'!$A6,'Registre de reserves'!$B$2:$B$1178,'2025'!V$2,Tabla1[ANY],'2025'!$Z$2) -> 0 | W6: =IF(V$4=0,0,V6/V$4) -> 0 | X6: =SUMIFS('Registre de reserves'!$P$2:$P$1178,'Registre de reserves'!$T$2:$T$1178,"SI",'Registre de reserves'!$I$2:$I$1178,'2025'!$A6,'Registre de reserves'!$B$2:$B$1178,'2025'!X$2,Tabla1[ANY],'2025'!$Z$2)+SUMIFS('Registre de reserves'!$U$2:$U$1178,'Registre de reserves'!$T$2:$T$1178,"RESERVA",'Registre de reserves'!$I$2:$I$1178,'2025'!$A6,'Registre de reserves'!$B$2:$B$1178,'2025'!X$2,Tabla1[ANY],'2025'!$Z$2) -> 0 | Y6: =IF(X$4=0,0,X6/X$4) -> 0 | Z6: =B6+D6+F6+H6+J6+L6+N6+P6+R6+T6+V6+X6 -> 8730 | AA6: =IF(Z$4=0,0,Z6/Z$4) -> 0.39218329 | AB6: =Z6/$A$2 -> 1455
A7: Dia sencer | B7: =SUMIFS('Registre de reserves'!$P$2:$P$1178,'Registre de reserves'!$T$2:$T$1178,"SI",'Registre de reserves'!$I$2:$I$1178,'2025'!$A7,'Registre de reserves'!$B$2:$B$1178,'2025'!B$2,Tabla1[ANY],'2025'!$Z$2)+SUMIFS('Registre de reserves'!$U$2:$U$1178,'Registre de reserves'!$T$2:$T$1178,"RESERVA",'Registre de reserves'!$I$2:$I$1178,'2025'!$A7,'Registre de reserves'!$B$2:$B$1178,'2025'!B$2,Tabla1[ANY],'2025'!$Z$2) -> 910 | C7: =IF(B$4=0,0,B7/B$4) -> 0.19934283 | D7: =SUMIFS('Registre de reserves'!$P$2:$P$1178,'Registre de reserves'!$T$2:$T$1178,"SI",'Registre de reserves'!$I$2:$I$1178,'2025'!$A7,'Registre de reserves'!$B$2:$B$1178,'2025'!D$2,Tabla1[ANY],'2025'!$Z$2)+SUMIFS('Registre de reserves'!$U$2:$U$1178,'Registre de reserves'!$T$2:$T$1178,"RESERVA",'Registre de reserves'!$I$2:$I$1178,'2025'!$A7,'Registre de reserves'!$B$2:$B$1178,'2025'!D$2,Tabla1[ANY],'2025'!$Z$2) -> 320 | E7: =IF(D$4=0,0,D7/D$4) -> 0.089260809 | F7: =SUMIFS('Registre de reserves'!$P$2:$P$1178,'Registre de reserves'!$T$2:$T$1178,"SI",'Registre de reserves'!$I$2:$I$1178,'2025'!$A7,'Registre de reserves'!$B$2:$B$1178,'2025'!F$2,Tabla1[ANY],'2025'!$Z$2)+SUMIFS('Registre de reserves'!$U$2:$U$1178,'Registre de reserves'!$T$2:$T$1178,"RESERVA",'Registre de reserves'!$I$2:$I$1178,'2025'!$A7,'Registre de reserves'!$B$2:$B$1178,'2025'!F$2,Tabla1[ANY],'2025'!$Z$2) -> 0 | G7: =IF(F$4=0,0,F7/F$4) -> 0 | H7: =SUMIFS('Registre de reserves'!$P$2:$P$1178,'Registre de reserves'!$T$2:$T$1178,"SI",'Registre de reserves'!$I$2:$I$1178,'2025'!$A7,'Registre de reserves'!$B$2:$B$1178,'2025'!H$2,Tabla1[ANY],'2025'!$Z$2)+SUMIFS('Registre de reserves'!$U$2:$U$1178,'Registre de reserves'!$T$2:$T$1178,"RESERVA",'Registre de reserves'!$I$2:$I$1178,'2025'!$A7,'Registre de reserves'!$B$2:$B$1178,'2025'!H$2,Tabla1[ANY],'2025'!$Z$2) -> 0 | I7: =IF(H$4=0,0,H7/H$4) -> 0 | J7: =SUMIFS('Registre de reserves'!$P$2:$P$1178,'Registre de reserves'!$T$2:$T$1178,"SI",'Registre de reserves'!$I$2:$I$1178,'2025'!$A7,'Registre de reserves'!$B$2:$B$1178,'2025'!J$2,Tabla1[ANY],'2025'!$Z$2)+SUMIFS('Registre de reserves'!$U$2:$U$1178,'Registre de reserves'!$T$2:$T$1178,"RESERVA",'Registre de reserves'!$I$2:$I$1178,'2025'!$A7,'Registre de reserves'!$B$2:$B$1178,'2025'!J$2,Tabla1[ANY],'2025'!$Z$2) -> 0 | K7: =IF(J$4=0,0,J7/J$4) -> 0 | L7: =SUMIFS('Registre de reserves'!$P$2:$P$1178,'Registre de reserves'!$T$2:$T$1178,"SI",'Registre de reserves'!$I$2:$I$1178,'2025'!$A7,'Registre de reserves'!$B$2:$B$1178,'2025'!L$2,Tabla1[ANY],'2025'!$Z$2)+SUMIFS('Registre de reserves'!$U$2:$U$1178,'Registre de reserves'!$T$2:$T$1178,"RESERVA",'Registre de reserves'!$I$2:$I$1178,'2025'!$A7,'Registre de reserves'!$B$2:$B$1178,'2025'!L$2,Tabla1[ANY],'2025'!$Z$2) -> 0 | M7: =IF(L$4=0,0,L7/L$4) -> 0 | N7: =SUMIFS('Registre de reserves'!$P$2:$P$1178,'Registre de reserves'!$T$2:$T$1178,"SI",'Registre de reserves'!$I$2:$I$1178,'2025'!$A7,'Registre de reserves'!$B$2:$B$1178,'2025'!N$2,Tabla1[ANY],'2025'!$Z$2)+SUMIFS('Registre de reserves'!$U$2:$U$1178,'Registre de reserves'!$T$2:$T$1178,"RESERVA",'Registre de reserves'!$I$2:$I$1178,'2025'!$A7,'Registre de reserves'!$B$2:$B$1178,'2025'!N$2,Tabla1[ANY],'2025'!$Z$2) -> 0 | O7: =IF(N$4=0,0,N7/N$4) -> 0 | P7: =SUMIFS('Registre de reserves'!$P$2:$P$1178,'Registre de reserves'!$T$2:$T$1178,"SI",'Registre de reserves'!$I$2:$I$1178,'2025'!$A7,'Registre de reserves'!$B$2:$B$1178,'2025'!P$2,Tabla1[ANY],'2025'!$Z$2)+SUMIFS('Registre de reserves'!$U$2:$U$1178,'Registre de reserves'!$T$2:$T$1178,"RESERVA",'Registre de reserves'!$I$2:$I$1178,'2025'!$A7,'Registre de reserves'!$B$2:$B$1178,'2025'!P$2,Tabla1[ANY],'2025'!$Z$2) -> 0 | Q7: =IF(P$4=0,0,P7/P$4) -> 0 | R7: =SUMIFS('Registre de reserves'!$P$2:$P$1178,'Registre de reserves'!$T$2:$T$1178,"SI",'Registre de reserves'!$I$2:$I$1178,'2025'!$A7,'Registre de reserves'!$B$2:$B$1178,'2025'!R$2,Tabla1[ANY],'2025'!$Z$2)+SUMIFS('Registre de reserves'!$U$2:$U$1178,'Registre de reserves'!$T$2:$T$1178,"RESERVA",'Registre de reserves'!$I$2:$I$1178,'2025'!$A7,'Registre de reserves'!$B$2:$B$1178,'2025'!R$2,Tabla1[ANY],'2025'!$Z$2) -> 0 | S7: =IF(R$4=0,0,R7/R$4) -> 0 | T7: =SUMIFS('Registre de reserves'!$P$2:$P$1178,'Registre de reserves'!$T$2:$T$1178,"SI",'Registre de reserves'!$I$2:$I$1178,'2025'!$A7,'Registre de reserves'!$B$2:$B$1178,'2025'!T$2,Tabla1[ANY],'2025'!$Z$2)+SUMIFS('Registre de reserves'!$U$2:$U$1178,'Registre de reserves'!$T$2:$T$1178,"RESERVA",'Registre de reserves'!$I$2:$I$1178,'2025'!$A7,'Registre de reserves'!$B$2:$B$1178,'2025'!T$2,Tabla1[ANY],'2025'!$Z$2) -> 0 | U7: =IF(T$4=0,0,T7/T$4) -> 0 | V7: =SUMIFS('Registre de reserves'!$P$2:$P$1178,'Registre de reserves'!$T$2:$T$1178,"SI",'Registre de reserves'!$I$2:$I$1178,'2025'!$A7,'Registre de reserves'!$B$2:$B$1178,'2025'!V$2,Tabla1[ANY],'2025'!$Z$2)+SUMIFS('Registre de reserves'!$U$2:$U$1178,'Registre de reserves'!$T$2:$T$1178,"RESERVA",'Registre de reserves'!$I$2:$I$1178,'2025'!$A7,'Registre de reserves'!$B$2:$B$1178,'2025'!V$2,Tabla1[ANY],'2025'!$Z$2) -> 0 | W7: =IF(V$4=0,0,V7/V$4) -> 0 | X7: =SUMIFS('Registre de reserves'!$P$2:$P$1178,'Registre de reserves'!$T$2:$T$1178,"SI",'Registre de reserves'!$I$2:$I$1178,'2025'!$A7,'Registre de reserves'!$B$2:$B$1178,'2025'!X$2,Tabla1[ANY],'2025'!$Z$2)+SUMIFS('Registre de reserves'!$U$2:$U$1178,'Registre de reserves'!$T$2:$T$1178,"RESERVA",'Registre de reserves'!$I$2:$I$1178,'2025'!$A7,'Registre de reserves'!$B$2:$B$1178,'2025'!X$2,Tabla1[ANY],'2025'!$Z$2) -> 0 | Y7: =IF(X$4=0,0,X7/X$4) -> 0 | Z7: =B7+D7+F7+H7+J7+L7+N7+P7+R7+T7+V7+X7 -> 1230 | AA7: =IF(Z$4=0,0,Z7/Z$4) -> 0.055256065 | AB7: =Z7/$A$2 -> 205
A8: Dinar | B8: =SUMIFS('Registre de reserves'!$P$2:$P$1178,'Registre de reserves'!$T$2:$T$1178,"SI",'Registre de reserves'!$I$2:$I$1178,'2025'!$A8,'Registre de reserves'!$B$2:$B$1178,'2025'!B$2,Tabla1[ANY],'2025'!$Z$2)+SUMIFS('Registre de reserves'!$U$2:$U$1178,'Registre de reserves'!$T$2:$T$1178,"RESERVA",'Registre de reserves'!$I$2:$I$1178,'2025'!$A8,'Registre de reserves'!$B$2:$B$1178,'2025'!B$2,Tabla1[ANY],'2025'!$Z$2) -> 0 | C8: =IF(B$4=0,0,B8/B$4) -> 0 | D8: =SUMIFS('Registre de reserves'!$P$2:$P$1178,'Registre de reserves'!$T$2:$T$1178,"SI",'Registre de reserves'!$I$2:$I$1178,'2025'!$A8,'Registre de reserves'!$B$2:$B$1178,'2025'!D$2,Tabla1[ANY],'2025'!$Z$2)+SUMIFS('Registre de reserves'!$U$2:$U$1178,'Registre de reserves'!$T$2:$T$1178,"RESERVA",'Registre de reserves'!$I$2:$I$1178,'2025'!$A8,'Registre de reserves'!$B$2:$B$1178,'2025'!D$2,Tabla1[ANY],'2025'!$Z$2) -> 0 | E8: =IF(D$4=0,0,D8/D$4) -> 0 | F8: =SUMIFS('Registre de reserves'!$P$2:$P$1178,'Registre de reserves'!$T$2:$T$1178,"SI",'Registre de reserves'!$I$2:$I$1178,'2025'!$A8,'Registre de reserves'!$B$2:$B$1178,'2025'!F$2,Tabla1[ANY],'2025'!$Z$2)+SUMIFS('Registre de reserves'!$U$2:$U$1178,'Registre de reserves'!$T$2:$T$1178,"RESERVA",'Registre de reserves'!$I$2:$I$1178,'2025'!$A8,'Registre de reserves'!$B$2:$B$1178,'2025'!F$2,Tabla1[ANY],'2025'!$Z$2) -> 0 | G8: =IF(F$4=0,0,F8/F$4) -> 0 | H8: =SUMIFS('Registre de reserves'!$P$2:$P$1178,'Registre de reserves'!$T$2:$T$1178,"SI",'Registre de reserves'!$I$2:$I$1178,'2025'!$A8,'Registre de reserves'!$B$2:$B$1178,'2025'!H$2,Tabla1[ANY],'2025'!$Z$2)+SUMIFS('Registre de reserves'!$U$2:$U$1178,'Registre de reserves'!$T$2:$T$1178,"RESERVA",'Registre de reserves'!$I$2:$I$1178,'2025'!$A8,'Registre de reserves'!$B$2:$B$1178,'2025'!H$2,Tabla1[ANY],'2025'!$Z$2) -> 0 | I8: =IF(H$4=0,0,H8/H$4) -> 0 | J8: =SUMIFS('Registre de reserves'!$P$2:$P$1178,'Registre de reserves'!$T$2:$T$1178,"SI",'Registre de reserves'!$I$2:$I$1178,'2025'!$A8,'Registre de reserves'!$B$2:$B$1178,'2025'!J$2,Tabla1[ANY],'2025'!$Z$2)+SUMIFS('Registre de reserves'!$U$2:$U$1178,'Registre de reserves'!$T$2:$T$1178,"RESERVA",'Registre de reserves'!$I$2:$I$1178,'2025'!$A8,'Registre de reserves'!$B$2:$B$1178,'2025'!J$2,Tabla1[ANY],'2025'!$Z$2) -> 0 | K8: =IF(J$4=0,0,J8/J$4) -> 0 | L8: =SUMIFS('Registre de reserves'!$P$2:$P$1178,'Registre de reserves'!$T$2:$T$1178,"SI",'Registre de reserves'!$I$2:$I$1178,'2025'!$A8,'Registre de reserves'!$B$2:$B$1178,'2025'!L$2,Tabla1[ANY],'2025'!$Z$2)+SUMIFS('Registre de reserves'!$U$2:$U$1178,'Registre de reserves'!$T$2:$T$1178,"RESERVA",'Registre de reserves'!$I$2:$I$1178,'2025'!$A8,'Registre de reserves'!$B$2:$B$1178,'2025'!L$2,Tabla1[ANY],'2025'!$Z$2) -> 0 | M8: =IF(L$4=0,0,L8/L$4) -> 0 | N8: =SUMIFS('Registre de reserves'!$P$2:$P$1178,'Registre de reserves'!$T$2:$T$1178,"SI",'Registre de reserves'!$I$2:$I$1178,'2025'!$A8,'Registre de reserves'!$B$2:$B$1178,'2025'!N$2,Tabla1[ANY],'2025'!$Z$2)+SUMIFS('Registre de reserves'!$U$2:$U$1178,'Registre de reserves'!$T$2:$T$1178,"RESERVA",'Registre de reserves'!$I$2:$I$1178,'2025'!$A8,'Registre de reserves'!$B$2:$B$1178,'2025'!N$2,Tabla1[ANY],'2025'!$Z$2) -> 0 | O8: =IF(N$4=0,0,N8/N$4) -> 0 | P8: =SUMIFS('Registre de reserves'!$P$2:$P$1178,'Registre de reserves'!$T$2:$T$1178,"SI",'Registre de reserves'!$I$2:$I$1178,'2025'!$A8,'Registre de reserves'!$B$2:$B$1178,'2025'!P$2,Tabla1[ANY],'2025'!$Z$2)+SUMIFS('Registre de reserves'!$U$2:$U$1178,'Registre de reserves'!$T$2:$T$1178,"RESERVA",'Registre de reserves'!$I$2:$I$1178,'2025'!$A8,'Registre de reserves'!$B$2:$B$1178,'2025'!P$2,Tabla1[ANY],'2025'!$Z$2) -> 0 | Q8: =IF(P$4=0,0,P8/P$4) -> 0 | R8: =SUMIFS('Registre de reserves'!$P$2:$P$1178,'Registre de reserves'!$T$2:$T$1178,"SI",'Registre de reserves'!$I$2:$I$1178,'2025'!$A8,'Registre de reserves'!$B$2:$B$1178,'2025'!R$2,Tabla1[ANY],'2025'!$Z$2)+SUMIFS('Registre de reserves'!$U$2:$U$1178,'Registre de reserves'!$T$2:$T$1178,"RESERVA",'Registre de reserves'!$I$2:$I$1178,'2025'!$A8,'Registre de reserves'!$B$2:$B$1178,'2025'!R$2,Tabla1[ANY],'2025'!$Z$2) -> 0 | S8: =IF(R$4=0,0,R8/R$4) -> 0 | T8: =SUMIFS('Registre de reserves'!$P$2:$P$1178,'Registre de reserves'!$T$2:$T$1178,"SI",'Registre de reserves'!$I$2:$I$1178,'2025'!$A8,'Registre de reserves'!$B$2:$B$1178,'2025'!T$2,Tabla1[ANY],'2025'!$Z$2)+SUMIFS('Registre de reserves'!$U$2:$U$1178,'Registre de reserves'!$T$2:$T$1178,"RESERVA",'Registre de reserves'!$I$2:$I$1178,'2025'!$A8,'Registre de reserves'!$B$2:$B$1178,'2025'!T$2,Tabla1[ANY],'2025'!$Z$2) -> 0 | U8: =IF(T$4=0,0,T8/T$4) -> 0 | V8: =SUMIFS('Registre de reserves'!$P$2:$P$1178,'Registre de reserves'!$T$2:$T$1178,"SI",'Registre de reserves'!$I$2:$I$1178,'2025'!$A8,'Registre de reserves'!$B$2:$B$1178,'2025'!V$2,Tabla1[ANY],'2025'!$Z$2)+SUMIFS('Registre de reserves'!$U$2:$U$1178,'Registre de reserves'!$T$2:$T$1178,"RESERVA",'Registre de reserves'!$I$2:$I$1178,'2025'!$A8,'Registre de reserves'!$B$2:$B$1178,'2025'!V$2,Tabla1[ANY],'2025'!$Z$2) -> 0 | W8: =IF(V$4=0,0,V8/V$4) -> 0 | X8: =SUMIFS('Registre de reserves'!$P$2:$P$1178,'Registre de reserves'!$T$2:$T$1178,"SI",'Registre de reserves'!$I$2:$I$1178,'2025'!$A8,'Registre de reserves'!$B$2:$B$1178,'2025'!X$2,Tabla1[ANY],'2025'!$Z$2)+SUMIFS('Registre de reserves'!$U$2:$U$1178,'Registre de reserves'!$T$2:$T$1178,"RESERVA",'Registre de reserves'!$I$2:$I$1178,'2025'!$A8,'Registre de reserves'!$B$2:$B$1178,'2025'!X$2,Tabla1[ANY],'2025'!$Z$2) -> 0 | Y8: =IF(X$4=0,0,X8/X$4) -> 0 | Z8: =B8+D8+F8+H8+J8+L8+N8+P8+R8+T8+V8+X8 -> 0 | AA8: =IF(Z$4=0,0,Z8/Z$4) -> 0 | AB8: =Z8/$A$2 -> 0
A9: Sopar | B9: =SUMIFS('Registre de reserves'!$P$2:$P$1178,'Registre de reserves'!$T$2:$T$1178,"SI",'Registre de reserves'!$I$2:$I$1178,'2025'!$A9,'Registre de reserves'!$B$2:$B$1178,'2025'!B$2,Tabla1[ANY],'2025'!$Z$2)+SUMIFS('Registre de reserves'!$U$2:$U$1178,'Registre de reserves'!$T$2:$T$1178,"RESERVA",'Registre de reserves'!$I$2:$I$1178,'2025'!$A9,'Registre de reserves'!$B$2:$B$1178,'2025'!B$2,Tabla1[ANY],'2025'!$Z$2) -> 0 | C9: =IF(B$4=0,0,B9/B$4) -> 0 | D9: =SUMIFS('Registre de reserves'!$P$2:$P$1178,'Registre de reserves'!$T$2:$T$1178,"SI",'Registre de reserves'!$I$2:$I$1178,'2025'!$A9,'Registre de reserves'!$B$2:$B$1178,'2025'!D$2,Tabla1[ANY],'2025'!$Z$2)+SUMIFS('Registre de reserves'!$U$2:$U$1178,'Registre de reserves'!$T$2:$T$1178,"RESERVA",'Registre de reserves'!$I$2:$I$1178,'2025'!$A9,'Registre de reserves'!$B$2:$B$1178,'2025'!D$2,Tabla1[ANY],'2025'!$Z$2) -> 0 | E9: =IF(D$4=0,0,D9/D$4) -> 0 | F9: =SUMIFS('Registre de reserves'!$P$2:$P$1178,'Registre de reserves'!$T$2:$T$1178,"SI",'Registre de reserves'!$I$2:$I$1178,'2025'!$A9,'Registre de reserves'!$B$2:$B$1178,'2025'!F$2,Tabla1[ANY],'2025'!$Z$2)+SUMIFS('Registre de reserves'!$U$2:$U$1178,'Registre de reserves'!$T$2:$T$1178,"RESERVA",'Registre de reserves'!$I$2:$I$1178,'2025'!$A9,'Registre de reserves'!$B$2:$B$1178,'2025'!F$2,Tabla1[ANY],'2025'!$Z$2) -> 0 | G9: =IF(F$4=0,0,F9/F$4) -> 0 | H9: =SUMIFS('Registre de reserves'!$P$2:$P$1178,'Registre de reserves'!$T$2:$T$1178,"SI",'Registre de reserves'!$I$2:$I$1178,'2025'!$A9,'Registre de reserves'!$B$2:$B$1178,'2025'!H$2,Tabla1[ANY],'2025'!$Z$2)+SUMIFS('Registre de reserves'!$U$2:$U$1178,'Registre de reserves'!$T$2:$T$1178,"RESERVA",'Registre de reserves'!$I$2:$I$1178,'2025'!$A9,'Registre de reserves'!$B$2:$B$1178,'2025'!H$2,Tabla1[ANY],'2025'!$Z$2) -> 0 | I9: =IF(H$4=0,0,H9/H$4) -> 0 | J9: =SUMIFS('Registre de reserves'!$P$2:$P$1178,'Registre de reserves'!$T$2:$T$1178,"SI",'Registre de reserves'!$I$2:$I$1178,'2025'!$A9,'Registre de reserves'!$B$2:$B$1178,'2025'!J$2,Tabla1[ANY],'2025'!$Z$2)+SUMIFS('Registre de reserves'!$U$2:$U$1178,'Registre de reserves'!$T$2:$T$1178,"RESERVA",'Registre de reserves'!$I$2:$I$1178,'2025'!$A9,'Registre de reserves'!$B$2:$B$1178,'2025'!J$2,Tabla1[ANY],'2025'!$Z$2) -> 0 | K9: =IF(J$4=0,0,J9/J$4) -> 0 | L9: =SUMIFS('Registre de reserves'!$P$2:$P$1178,'Registre de reserves'!$T$2:$T$1178,"SI",'Registre de reserves'!$I$2:$I$1178,'2025'!$A9,'Registre de reserves'!$B$2:$B$1178,'2025'!L$2,Tabla1[ANY],'2025'!$Z$2)+SUMIFS('Registre de reserves'!$U$2:$U$1178,'Registre de reserves'!$T$2:$T$1178,"RESERVA",'Registre de reserves'!$I$2:$I$1178,'2025'!$A9,'Registre de reserves'!$B$2:$B$1178,'2025'!L$2,Tabla1[ANY],'2025'!$Z$2) -> 0 | M9: =IF(L$4=0,0,L9/L$4) -> 0 | N9: =SUMIFS('Registre de reserves'!$P$2:$P$1178,'Registre de reserves'!$T$2:$T$1178,"SI",'Registre de reserves'!$I$2:$I$1178,'2025'!$A9,'Registre de reserves'!$B$2:$B$1178,'2025'!N$2,Tabla1[ANY],'2025'!$Z$2)+SUMIFS('Registre de reserves'!$U$2:$U$1178,'Registre de reserves'!$T$2:$T$1178,"RESERVA",'Registre de reserves'!$I$2:$I$1178,'2025'!$A9,'Registre de reserves'!$B$2:$B$1178,'2025'!N$2,Tabla1[ANY],'2025'!$Z$2) -> 0 | O9: =IF(N$4=0,0,N9/N$4) -> 0 | P9: =SUMIFS('Registre de reserves'!$P$2:$P$1178,'Registre de reserves'!$T$2:$T$1178,"SI",'Registre de reserves'!$I$2:$I$1178,'2025'!$A9,'Registre de reserves'!$B$2:$B$1178,'2025'!P$2,Tabla1[ANY],'2025'!$Z$2)+SUMIFS('Registre de reserves'!$U$2:$U$1178,'Registre de reserves'!$T$2:$T$1178,"RESERVA",'Registre de reserves'!$I$2:$I$1178,'2025'!$A9,'Registre de reserves'!$B$2:$B$1178,'2025'!P$2,Tabla1[ANY],'2025'!$Z$2) -> 0 | Q9: =IF(P$4=0,0,P9/P$4) -> 0 | R9: =SUMIFS('Registre de reserves'!$P$2:$P$1178,'Registre de reserves'!$T$2:$T$1178,"SI",'Registre de reserves'!$I$2:$I$1178,'2025'!$A9,'Registre de reserves'!$B$2:$B$1178,'2025'!R$2,Tabla1[ANY],'2025'!$Z$2)+SUMIFS('Registre de reserves'!$U$2:$U$1178,'Registre de reserves'!$T$2:$T$1178,"RESERVA",'Registre de reserves'!$I$2:$I$1178,'2025'!$A9,'Registre de reserves'!$B$2:$B$1178,'2025'!R$2,Tabla1[ANY],'2025'!$Z$2) -> 0 | S9: =IF(R$4=0,0,R9/R$4) -> 0 | T9: =SUMIFS('Registre de reserves'!$P$2:$P$1178,'Registre de reserves'!$T$2:$T$1178,"SI",'Registre de reserves'!$I$2:$I$1178,'2025'!$A9,'Registre de reserves'!$B$2:$B$1178,'2025'!T$2,Tabla1[ANY],'2025'!$Z$2)+SUMIFS('Registre de reserves'!$U$2:$U$1178,'Registre de reserves'!$T$2:$T$1178,"RESERVA",'Registre de reserves'!$I$2:$I$1178,'2025'!$A9,'Registre de reserves'!$B$2:$B$1178,'2025'!T$2,Tabla1[ANY],'2025'!$Z$2) -> 0 | U9: =IF(T$4=0,0,T9/T$4) -> 0 | V9: =SUMIFS('Registre de reserves'!$P$2:$P$1178,'Registre de reserves'!$T$2:$T$1178,"SI",'Registre de reserves'!$I$2:$I$1178,'2025'!$A9,'Registre de reserves'!$B$2:$B$1178,'2025'!V$2,Tabla1[ANY],'2025'!$Z$2)+SUMIFS('Registre de reserves'!$U$2:$U$1178,'Registre de reserves'!$T$2:$T$1178,"RESERVA",'Registre de reserves'!$I$2:$I$1178,'2025'!$A9,'Registre de reserves'!$B$2:$B$1178,'2025'!V$2,Tabla1[ANY],'2025'!$Z$2) -> 0 | W9: =IF(V$4=0,0,V9/V$4) -> 0 | X9: =SUMIFS('Registre de reserves'!$P$2:$P$1178,'Registre de reserves'!$T$2:$T$1178,"SI",'Registre de reserves'!$I$2:$I$1178,'2025'!$A9,'Registre de reserves'!$B$2:$B$1178,'2025'!X$2,Tabla1[ANY],'2025'!$Z$2)+SUMIFS('Registre de reserves'!$U$2:$U$1178,'Registre de reserves'!$T$2:$T$1178,"RESERVA",'Registre de reserves'!$I$2:$I$1178,'2025'!$A9,'Registre de reserves'!$B$2:$B$1178,'2025'!X$2,Tabla1[ANY],'2025'!$Z$2) -> 0 | Y9: =IF(X$4=0,0,X9/X$4) -> 0 | Z9: =B9+D9+F9+H9+J9+L9+N9+P9+R9+T9+V9+X9 -> 0 | AA9: =IF(Z$4=0,0,Z9/Z$4) -> 0 | AB9: =Z9/$A$2 -> 0
